OperationalError
sqlalchemy.exc.OperationalError: (sqlite3.OperationalError) no such column: ad_watch_session.direct_ads_watched_count
[SQL: SELECT ad_watch_session.id AS ad_watch_session_id, ad_watch_session.user_id AS ad_watch_session_user_id, ad_watch_session.session_date AS ad_watch_session_session_date, ad_watch_session.ads_watched_count AS ad_watch_session_ads_watched_count, ad_watch_session.direct_ads_watched_count AS ad_watch_session_direct_ads_watched_count, ad_watch_session.last_ad_time AS ad_watch_session_last_ad_time, ad_watch_session.last_direct_ad_time AS ad_watch_session_last_direct_ad_time, ad_watch_session.cooldown_until AS ad_watch_session_cooldown_until, ad_watch_session.direct_cooldown_until AS ad_watch_session_direct_cooldown_until, ad_watch_session.is_active AS ad_watch_session_is_active, ad_watch_session.created_at AS ad_watch_session_created_at 
FROM ad_watch_session 
WHERE ad_watch_session.user_id = ? AND ad_watch_session.session_date = ?
 LIMIT ? OFFSET ?]
[parameters: (1, '2025-06-10', 1, 0)]
(Background on this error at: https://sqlalche.me/e/20/e3q8)

Traceback (most recent call last)
File "/home/runner/workspace/.pythonlibs/lib/python3.11/site-packages/sqlalchemy/engine/base.py", line 1963, in _exec_single_context
self.dialect.do_execute(
^
File "/home/runner/workspace/.pythonlibs/lib/python3.11/site-packages/sqlalchemy/engine/default.py", line 943, in do_execute
cursor.execute(statement, parameters)
^^^^^^^^^^^^^^^^^^^^^^^^^^^^^^^^^^^^^
The above exception was the direct cause of the following exception:
File "/home/runner/workspace/.pythonlibs/lib/python3.11/site-packages/flask/app.py", line 2213, in __call__
return self.wsgi_app(environ, start_response)
       ^^^^^^^^^^^^^^^^^^^^^^^^^^^^^^^^^^^^^^
File "/home/runner/workspace/.pythonlibs/lib/python3.11/site-packages/flask/app.py", line 2193, in wsgi_app
response = self.handle_exception(e)
           ^^^^^^^^^^^^^^^^^^^^^^^^
File "/home/runner/workspace/.pythonlibs/lib/python3.11/site-packages/flask/app.py", line 2190, in wsgi_app
response = self.full_dispatch_request()
           ^^^^^^^^^^^^^^^^^^^^^^^^^^^^
File "/home/runner/workspace/.pythonlibs/lib/python3.11/site-packages/flask/app.py", line 1486, in full_dispatch_request
rv = self.handle_user_exception(e)
     ^^^^^^^^^^^^^^^^^^^^^^^^^^^^^
File "/home/runner/workspace/.pythonlibs/lib/python3.11/site-packages/flask/app.py", line 1484, in full_dispatch_request
rv = self.dispatch_request()
     ^^^^^^^^^^^^^^^^^^^^^^^
File "/home/runner/workspace/.pythonlibs/lib/python3.11/site-packages/flask/app.py", line 1469, in dispatch_request
return self.ensure_sync(self.view_functions[rule.endpoint])(**view_args)
       ^^^^^^^^^^^^^^^^^^^^^^^^^^^^^^^^^^^^^^^^^^^^^^^^^^^^^^^^^^^^^^^^^
File "/home/runner/workspace/main.py", line 1624, in admin_panel
ad_session = AdWatchSession.query.filter_by(user_id=user.id, session_date=today).first()
             ^^^^^^^^^^^^^^^^^^^^^^^^^^^^^^^^^^^^^^^^^^^^^^^^^^^^^^^^^^^^^^^^^^^^^^^^^^^
File "/home/runner/workspace/.pythonlibs/lib/python3.11/site-packages/sqlalchemy/orm/query.py", line 2759, in first
return self.limit(1)._iter().first()  # type: ignore
       ^^^^^^^^^^^^^^^^^^^^^
File "/home/runner/workspace/.pythonlibs/lib/python3.11/site-packages/sqlalchemy/orm/query.py", line 2857, in _iter
result: Union[ScalarResult[_T], Result[_T]] = self.session.execute(
                                              
File "/home/runner/workspace/.pythonlibs/lib/python3.11/site-packages/sqlalchemy/orm/session.py", line 2365, in execute
return self._execute_internal(
       
File "/home/runner/workspace/.pythonlibs/lib/python3.11/site-packages/sqlalchemy/orm/session.py", line 2251, in _execute_internal
result: Result[Any] = compile_state_cls.orm_execute_statement(
                      
File "/home/runner/workspace/.pythonlibs/lib/python3.11/site-packages/sqlalchemy/orm/context.py", line 306, in orm_execute_statement
result = conn.execute(
         
File "/home/runner/workspace/.pythonlibs/lib/python3.11/site-packages/sqlalchemy/engine/base.py", line 1415, in execute
return meth(
       
File "/home/runner/workspace/.pythonlibs/lib/python3.11/site-packages/sqlalchemy/sql/elements.py", line 523, in _execute_on_connection
return connection._execute_clauseelement(
       
File "/home/runner/workspace/.pythonlibs/lib/python3.11/site-packages/sqlalchemy/engine/base.py", line 1637, in _execute_clauseelement
ret = self._execute_context(
      
File "/home/runner/workspace/.pythonlibs/lib/python3.11/site-packages/sqlalchemy/engine/base.py", line 1842, in _execute_context
return self._exec_single_context(
       
File "/home/runner/workspace/.pythonlibs/lib/python3.11/site-packages/sqlalchemy/engine/base.py", line 1982, in _exec_single_context
self._handle_dbapi_exception(
^
File "/home/runner/workspace/.pythonlibs/lib/python3.11/site-packages/sqlalchemy/engine/base.py", line 2351, in _handle_dbapi_exception
raise sqlalchemy_exception.with_traceback(exc_info[2]) from e
^^^^^^^^^^^^^^^^^^^^^^^^^^^^^^^^^^^^^^^^^^^^^^^^^^^^^^^^^^^^^
File "/home/runner/workspace/.pythonlibs/lib/python3.11/site-packages/sqlalchemy/engine/base.py", line 1963, in _exec_single_context
self.dialect.do_execute(
^
File "/home/runner/workspace/.pythonlibs/lib/python3.11/site-packages/sqlalchemy/engine/default.py", line 943, in do_execute
cursor.execute(statement, parameters)
^^^^^^^^^^^^^^^^^^^^^^^^^^^^^^^^^^^^^
sqlalchemy.exc.OperationalError: (sqlite3.OperationalError) no such column: ad_watch_session.direct_ads_watched_count
[SQL: SELECT ad_watch_session.id AS ad_watch_session_id, ad_watch_session.user_id AS ad_watch_session_user_id, ad_watch_session.session_date AS ad_watch_session_session_date, ad_watch_session.ads_watched_count AS ad_watch_session_ads_watched_count, ad_watch_session.direct_ads_watched_count AS ad_watch_session_direct_ads_watched_count, ad_watch_session.last_ad_time AS ad_watch_session_last_ad_time, ad_watch_session.last_direct_ad_time AS ad_watch_session_last_direct_ad_time, ad_watch_session.cooldown_until AS ad_watch_session_cooldown_until, ad_watch_session.direct_cooldown_until AS ad_watch_session_direct_cooldown_until, ad_watch_session.is_active AS ad_watch_session_is_active, ad_watch_session.created_at AS ad_watch_session_created_at
FROM ad_watch_session
WHERE ad_watch_session.user_id = ? AND ad_watch_session.session_date = ?
LIMIT ? OFFSET ?]
[parameters: (1, '2025-06-10', 1, 0)]
(Background on this error at: https://sqlalche.me/e/20/e3q8)